Workbook

Sheet Data
A1: 1 | B1: apple | C1: 10.5 | D1: =TRUE() -> TRUE | E1: 45306 | F1: 100 | G1: one hundred | H1: =1/0 -> #DIV/0! | K1: =SUM(1,2,3) | L1: =SUM(1,2,3) -> 6
A2: 2 | B2: banana | C2: -2 | D2: =FALSE() -> FALSE | E2: 45657 | F2: 200 | G2: two hundred | H2: =NA() -> #N/A | K2: =SUM(A1:A6) | L2: =SUM(A1:A6) -> 21
A3: 3 | B3: cherry | C3: 0 | D3: ="" | E3: 45306.75 | F3: 300 | G3: three hundred | K3: =SUM(C1:C6) | L3: =SUM(C1:C6) -> 1000111.8
A4: 4 | B4: date | C4: 100 | E4: 0.5 | F4: 400 | G4: four hundred | K4: =SUM(D1:D6) | L4: =SUM(D1:D6) -> 1
A5: 5 | B5: elderberry | C5: 3.25 | D5: 42 | K5: =SUM(B1:B3) | L5: =SUM(B1:B3) -> 0
A6: 6 | B6: fig | C6: 1000000 | D6: padded | K6: =SUM("3",4) | L6: =SUM("3",4) -> #VALUE!
K7: =SUM(TRUE,1) | L7: =SUM(TRUE(),1) -> 2
K8: =SUM(A1:A3,H1) | L8: =SUM(A1:A3,H1) -> #DIV/0!
K9: =SUM(H1:H2) | L9: =SUM(H1:H2) -> #DIV/0!
K10: =SUM(A1:A2,D4) | L10: =SUM(A1:A2,D4) -> 3
K11: =AVERAGE(A1:A6) | L11: =AVERAGE(A1:A6) -> 3.5
K12: =AVERAGE(C1:C4) | L12: =AVERAGE(C1:C4) -> 27.125
K13: =AVERAGE(B1:B3) | L13: =AVERAGE(B1:B3) -> #DIV/0!
K14: =AVERAGE(A1,H1) | L14: =AVERAGE(A1,H1) -> #DIV/0!
K15: =AVERAGE(D1:D6) | L15: =AVERAGE(D1:D6) -> 0.5
K16: =AVERAGE(1,"3") | L16: =AVERAGE(1,"3") -> #VALUE!
K17: =AVERAGE(A1:A2,D4) | L17: =AVERAGE(A1:A2,D4) -> 1.5
K18: =AVERAGE(0,0) | L18: =AVERAGE(0,0) -> 0
K19: =MIN(C1:C6) | L19: =MIN(C1:C6) -> -2
K20: =MIN(1,2,-3) | L20: =MIN(1,2,-3) -> -3
K21: =MIN(B1:B3) | L21: =MIN(B1:B3) -> 0
K22: =MIN(A1:A3,H1) | L22: =MIN(A1:A3,H1) -> #DIV/0!
K23: =MIN(D1:D2) | L23: =MIN(D1:D2) -> FALSE
K24: =MIN(TRUE,5) | L24: =MIN(TRUE(),5) -> 1
K25: =MIN(C1:C3,D4) | L25: =MIN(C1:C3,D4) -> -2
K26: =MAX(C1:C6) | L26: =MAX(C1:C6) -> 1000000
K27: =MAX(-5,-2) | L27: =MAX(-5,-2) -> -2
K28: =MAX(B1:B3) | L28: =MAX(B1:B3) -> 0
K29: =MAX(H2,1) | L29: =MAX(H2,1) -> #N/A
K30: =MAX(D4,-1) | L30: =MAX(D4,-1) -> -1
K31: =MAX(A1:A6,"x") | L31: =MAX(A1:A6,"x") -> #VALUE!
K32: =MAX(-3,D4) | L32: =MAX(-3,D4) -> -3
K33: =COUNT(A1:A6) | L33: =COUNT(A1:A6) -> 6
K34: =COUNT(A1:D6) | L34: =COUNT(A1:D6) -> 14
K35: =COUNT(1,"a",TRUE) | L35: =COUNT(1,"a",TRUE()) -> 2
K36: =COUNT(B1:B6) | L36: =COUNT(B1:B6) -> 0
K37: =COUNT(H1:H2) | L37: =COUNT(H1:H2) -> 0
K38: =COUNT(D1:D6) | L38: =COUNT(D1:D6) -> 2
K39: =COUNT(E1:E4) | L39: =COUNT(E1:E4) -> 4
K40: =COUNT("5") | L40: =COUNT("5") -> 1
...

Sheet Other
A1: 7 | B1: remote
